[2021-10-18 20:38:19,507] {taskinstance.py:1035} INFO - Dependencies all met for <TaskInstance: Neo4jOlympicsDemo.create-db manual__2021-10-18T20:38:18.935137+00:00 [queued]>
[2021-10-18 20:38:19,522] {taskinstance.py:1035} INFO - Dependencies all met for <TaskInstance: Neo4jOlympicsDemo.create-db manual__2021-10-18T20:38:18.935137+00:00 [queued]>
[2021-10-18 20:38:19,523] {taskinstance.py:1241} INFO - 
--------------------------------------------------------------------------------
[2021-10-18 20:38:19,523] {taskinstance.py:1242} INFO - Starting attempt 1 of 2
[2021-10-18 20:38:19,524] {taskinstance.py:1243} INFO - 
--------------------------------------------------------------------------------
[2021-10-18 20:38:19,532] {taskinstance.py:1262} INFO - Executing <Task(PythonOperator): create-db> on 2021-10-18 20:38:18.935137+00:00
[2021-10-18 20:38:19,539] {standard_task_runner.py:76} INFO - Running: ['***', 'tasks', 'run', 'Neo4jOlympicsDemo', 'create-db', 'manual__2021-10-18T20:38:18.935137+00:00', '--job-id', '6', '--raw', '--subdir', 'DAGS_FOLDER/olympics.py', '--cfg-path', '/tmp/tmpbmtooimu', '--error-file', '/tmp/tmpfi09pod7']
[2021-10-18 20:38:19,541] {standard_task_runner.py:77} INFO - Job 6: Subtask create-db
[2021-10-18 20:38:19,536] {standard_task_runner.py:52} INFO - Started process 519 to run task
[2021-10-18 20:38:19,576] {logging_mixin.py:109} INFO - Running <TaskInstance: Neo4jOlympicsDemo.create-db manual__2021-10-18T20:38:18.935137+00:00 [running]> on host 668276dc515d
[2021-10-18 20:38:19,615] {taskinstance.py:1414} INFO - Exporting the following env vars:
AIRFLOW_CTX_DAG_EMAIL=alexander.fournier@gmail.com
AIRFLOW_CTX_DAG_OWNER=Alexander Fournier
AIRFLOW_CTX_DAG_ID=Neo4jOlympicsDemo
AIRFLOW_CTX_TASK_ID=create-db
AIRFLOW_CTX_EXECUTION_DATE=2021-10-18T20:38:18.935137+00:00
AIRFLOW_CTX_DAG_RUN_ID=manual__2021-10-18T20:38:18.935137+00:00
[2021-10-18 20:38:19,621] {simple.py:361} WARNING - Transaction failed and will be retried in 0.9959179212703559s (Couldn't connect to 127.0.0.1:7474 (resolved to ('127.0.0.1:7474',)):
Failed to establish connection to ResolvedIPv4Address(('127.0.0.1', 7474)) (reason [Errno 111] Connection refused))
[2021-10-18 20:38:20,618] {simple.py:361} WARNING - Transaction failed and will be retried in 2.052442287619309s (Couldn't connect to 127.0.0.1:7474 (resolved to ('127.0.0.1:7474',)):
Failed to establish connection to ResolvedIPv4Address(('127.0.0.1', 7474)) (reason [Errno 111] Connection refused))
[2021-10-18 20:38:22,673] {simple.py:361} WARNING - Transaction failed and will be retried in 3.944826901284462s (Couldn't connect to 127.0.0.1:7474 (resolved to ('127.0.0.1:7474',)):
Failed to establish connection to ResolvedIPv4Address(('127.0.0.1', 7474)) (reason [Errno 111] Connection refused))
[2021-10-18 20:38:26,622] {simple.py:361} WARNING - Transaction failed and will be retried in 8.205300111871818s (Couldn't connect to 127.0.0.1:7474 (resolved to ('127.0.0.1:7474',)):
Failed to establish connection to ResolvedIPv4Address(('127.0.0.1', 7474)) (reason [Errno 111] Connection refused))
[2021-10-18 20:38:34,812] {simple.py:361} WARNING - Transaction failed and will be retried in 14.569736607669716s (Couldn't connect to 127.0.0.1:7474 (resolved to ('127.0.0.1:7474',)):
Failed to establish connection to ResolvedIPv4Address(('127.0.0.1', 7474)) (reason [Errno 111] Connection refused))
[2021-10-18 20:38:49,399] {simple.py:361} WARNING - Transaction failed and will be retried in 28.59270443906546s (Couldn't connect to 127.0.0.1:7474 (resolved to ('127.0.0.1:7474',)):
Failed to establish connection to ResolvedIPv4Address(('127.0.0.1', 7474)) (reason [Errno 111] Connection refused))
[2021-10-18 20:39:17,992] {taskinstance.py:1686} ERROR - Task failed with exception
Traceback (most recent call last):
  File "/home/airflow/.local/lib/python3.6/site-packages/neo4j/io/__init__.py", line 1181, in _connect
    s.connect(resolved_address)
ConnectionRefusedError: [Errno 111] Connection refused

During handling of the above exception, another exception occurred:

Traceback (most recent call last):
  File "/home/airflow/.local/lib/python3.6/site-packages/neo4j/io/__init__.py", line 1301, in connect
    s = _connect(resolved_address, timeout, keep_alive)
  File "/home/airflow/.local/lib/python3.6/site-packages/neo4j/io/__init__.py", line 1195, in _connect
    raise ServiceUnavailable("Failed to establish connection to {!r} (reason {})".format(resolved_address, error))
neo4j.exceptions.ServiceUnavailable: Failed to establish connection to ResolvedIPv4Address(('127.0.0.1', 7474)) (reason [Errno 111] Connection refused)

The above exception was the direct cause of the following exception:

Traceback (most recent call last):
  File "/home/airflow/.local/lib/python3.6/site-packages/airflow/models/taskinstance.py", line 1324, in _run_raw_task
    self._execute_task_with_callbacks(context)
  File "/home/airflow/.local/lib/python3.6/site-packages/airflow/models/taskinstance.py", line 1443, in _execute_task_with_callbacks
    result = self._execute_task(context, self.task)
  File "/home/airflow/.local/lib/python3.6/site-packages/airflow/models/taskinstance.py", line 1499, in _execute_task
    result = execute_callable(context=context)
  File "/home/airflow/.local/lib/python3.6/site-packages/airflow/operators/python.py", line 151, in execute
    return_value = self.execute_callable()
  File "/home/airflow/.local/lib/python3.6/site-packages/airflow/operators/python.py", line 162, in execute_callable
    return self.python_callable(*self.op_args, **self.op_kwargs)
  File "/opt/airflow/dags/package/create_database.py", line 8, in create_database
    db.write(q)
  File "/opt/airflow/dags/package/connection.py", line 36, in write
    return session.write_transaction(self.__run, query)
  File "/home/airflow/.local/lib/python3.6/site-packages/neo4j/work/simple.py", line 434, in write_transaction
    return self._run_transaction(WRITE_ACCESS, transaction_function, *args, **kwargs)
  File "/home/airflow/.local/lib/python3.6/site-packages/neo4j/work/simple.py", line 365, in _run_transaction
    raise errors[-1]
  File "/home/airflow/.local/lib/python3.6/site-packages/neo4j/work/simple.py", line 335, in _run_transaction
    self._open_transaction(access_mode=access_mode, database=self._config.database, metadata=metadata, timeout=timeout)
  File "/home/airflow/.local/lib/python3.6/site-packages/neo4j/work/simple.py", line 271, in _open_transaction
    self._connect(access_mode=access_mode, database=database)
  File "/home/airflow/.local/lib/python3.6/site-packages/neo4j/work/simple.py", line 122, in _connect
    bookmarks=self._bookmarks
  File "/home/airflow/.local/lib/python3.6/site-packages/neo4j/io/__init__.py", line 810, in acquire
    return self._acquire(self.address, timeout)
  File "/home/airflow/.local/lib/python3.6/site-packages/neo4j/io/__init__.py", line 665, in _acquire
    connection = self.opener(address, timeout)
  File "/home/airflow/.local/lib/python3.6/site-packages/neo4j/io/__init__.py", line 794, in opener
    **pool_config
  File "/home/airflow/.local/lib/python3.6/site-packages/neo4j/io/__init__.py", line 314, in open
    keep_alive=pool_config.keep_alive,
  File "/home/airflow/.local/lib/python3.6/site-packages/neo4j/io/__init__.py", line 1323, in connect
    ) from errors[0]
neo4j.exceptions.ServiceUnavailable: Couldn't connect to 127.0.0.1:7474 (resolved to ('127.0.0.1:7474',)):
Failed to establish connection to ResolvedIPv4Address(('127.0.0.1', 7474)) (reason [Errno 111] Connection refused)
[2021-10-18 20:39:18,005] {taskinstance.py:1280} INFO - Marking task as UP_FOR_RETRY. dag_id=Neo4jOlympicsDemo, task_id=create-db, execution_date=20211018T203818, start_date=20211018T203819, end_date=20211018T203918
[2021-10-18 20:39:18,016] {standard_task_runner.py:91} ERROR - Failed to execute job 6 for task create-db
Traceback (most recent call last):
  File "/home/airflow/.local/lib/python3.6/site-packages/neo4j/io/__init__.py", line 1181, in _connect
    s.connect(resolved_address)
ConnectionRefusedError: [Errno 111] Connection refused

During handling of the above exception, another exception occurred:

Traceback (most recent call last):
  File "/home/airflow/.local/lib/python3.6/site-packages/neo4j/io/__init__.py", line 1301, in connect
    s = _connect(resolved_address, timeout, keep_alive)
  File "/home/airflow/.local/lib/python3.6/site-packages/neo4j/io/__init__.py", line 1195, in _connect
    raise ServiceUnavailable("Failed to establish connection to {!r} (reason {})".format(resolved_address, error))
neo4j.exceptions.ServiceUnavailable: Failed to establish connection to ResolvedIPv4Address(('127.0.0.1', 7474)) (reason [Errno 111] Connection refused)

The above exception was the direct cause of the following exception:

Traceback (most recent call last):
  File "/home/airflow/.local/lib/python3.6/site-packages/airflow/task/task_runner/standard_task_runner.py", line 85, in _start_by_fork
    args.func(args, dag=self.dag)
  File "/home/airflow/.local/lib/python3.6/site-packages/airflow/cli/cli_parser.py", line 48, in command
    return func(*args, **kwargs)
  File "/home/airflow/.local/lib/python3.6/site-packages/airflow/utils/cli.py", line 92, in wrapper
    return f(*args, **kwargs)
  File "/home/airflow/.local/lib/python3.6/site-packages/airflow/cli/commands/task_command.py", line 292, in task_run
    _run_task_by_selected_method(args, dag, ti)
  File "/home/airflow/.local/lib/python3.6/site-packages/airflow/cli/commands/task_command.py", line 107, in _run_task_by_selected_method
    _run_raw_task(args, ti)
  File "/home/airflow/.local/lib/python3.6/site-packages/airflow/cli/commands/task_command.py", line 184, in _run_raw_task
    error_file=args.error_file,
  File "/home/airflow/.local/lib/python3.6/site-packages/airflow/utils/session.py", line 70, in wrapper
    return func(*args, session=session, **kwargs)
  File "/home/airflow/.local/lib/python3.6/site-packages/airflow/models/taskinstance.py", line 1324, in _run_raw_task
    self._execute_task_with_callbacks(context)
  File "/home/airflow/.local/lib/python3.6/site-packages/airflow/models/taskinstance.py", line 1443, in _execute_task_with_callbacks
    result = self._execute_task(context, self.task)
  File "/home/airflow/.local/lib/python3.6/site-packages/airflow/models/taskinstance.py", line 1499, in _execute_task
    result = execute_callable(context=context)
  File "/home/airflow/.local/lib/python3.6/site-packages/airflow/operators/python.py", line 151, in execute
    return_value = self.execute_callable()
  File "/home/airflow/.local/lib/python3.6/site-packages/airflow/operators/python.py", line 162, in execute_callable
    return self.python_callable(*self.op_args, **self.op_kwargs)
  File "/opt/airflow/dags/package/create_database.py", line 8, in create_database
    db.write(q)
  File "/opt/airflow/dags/package/connection.py", line 36, in write
    return session.write_transaction(self.__run, query)
  File "/home/airflow/.local/lib/python3.6/site-packages/neo4j/work/simple.py", line 434, in write_transaction
    return self._run_transaction(WRITE_ACCESS, transaction_function, *args, **kwargs)
  File "/home/airflow/.local/lib/python3.6/site-packages/neo4j/work/simple.py", line 365, in _run_transaction
    raise errors[-1]
  File "/home/airflow/.local/lib/python3.6/site-packages/neo4j/work/simple.py", line 335, in _run_transaction
    self._open_transaction(access_mode=access_mode, database=self._config.database, metadata=metadata, timeout=timeout)
  File "/home/airflow/.local/lib/python3.6/site-packages/neo4j/work/simple.py", line 271, in _open_transaction
    self._connect(access_mode=access_mode, database=database)
  File "/home/airflow/.local/lib/python3.6/site-packages/neo4j/work/simple.py", line 122, in _connect
    bookmarks=self._bookmarks
  File "/home/airflow/.local/lib/python3.6/site-packages/neo4j/io/__init__.py", line 810, in acquire
    return self._acquire(self.address, timeout)
  File "/home/airflow/.local/lib/python3.6/site-packages/neo4j/io/__init__.py", line 665, in _acquire
    connection = self.opener(address, timeout)
  File "/home/airflow/.local/lib/python3.6/site-packages/neo4j/io/__init__.py", line 794, in opener
    **pool_config
  File "/home/airflow/.local/lib/python3.6/site-packages/neo4j/io/__init__.py", line 314, in open
    keep_alive=pool_config.keep_alive,
  File "/home/airflow/.local/lib/python3.6/site-packages/neo4j/io/__init__.py", line 1323, in connect
    ) from errors[0]
neo4j.exceptions.ServiceUnavailable: Couldn't connect to 127.0.0.1:7474 (resolved to ('127.0.0.1:7474',)):
Failed to establish connection to ResolvedIPv4Address(('127.0.0.1', 7474)) (reason [Errno 111] Connection refused)
[2021-10-18 20:39:18,052] {local_task_job.py:154} INFO - Task exited with return code 1
[2021-10-18 20:39:18,081] {local_task_job.py:264} INFO - 0 downstream tasks scheduled from follow-on schedule check
