[2021-10-18 20:44:18,642] {taskinstance.py:1035} INFO - Dependencies all met for <TaskInstance: Neo4jOlympicsDemo.create-db manual__2021-10-18T20:38:18.935137+00:00 [queued]>
[2021-10-18 20:44:18,656] {taskinstance.py:1035} INFO - Dependencies all met for <TaskInstance: Neo4jOlympicsDemo.create-db manual__2021-10-18T20:38:18.935137+00:00 [queued]>
[2021-10-18 20:44:18,656] {taskinstance.py:1241} INFO - 
--------------------------------------------------------------------------------
[2021-10-18 20:44:18,657] {taskinstance.py:1242} INFO - Starting attempt 2 of 2
[2021-10-18 20:44:18,657] {taskinstance.py:1243} INFO - 
--------------------------------------------------------------------------------
[2021-10-18 20:44:18,665] {taskinstance.py:1262} INFO - Executing <Task(PythonOperator): create-db> on 2021-10-18 20:38:18.935137+00:00
[2021-10-18 20:44:18,674] {standard_task_runner.py:76} INFO - Running: ['***', 'tasks', 'run', 'Neo4jOlympicsDemo', 'create-db', 'manual__2021-10-18T20:38:18.935137+00:00', '--job-id', '11', '--raw', '--subdir', 'DAGS_FOLDER/olympics.py', '--cfg-path', '/tmp/tmp0k6fe1lm', '--error-file', '/tmp/tmp2w95e97x']
[2021-10-18 20:44:18,675] {standard_task_runner.py:77} INFO - Job 11: Subtask create-db
[2021-10-18 20:44:18,670] {standard_task_runner.py:52} INFO - Started process 826 to run task
[2021-10-18 20:44:18,710] {logging_mixin.py:109} INFO - Running <TaskInstance: Neo4jOlympicsDemo.create-db manual__2021-10-18T20:38:18.935137+00:00 [running]> on host 668276dc515d
[2021-10-18 20:44:18,746] {taskinstance.py:1414} INFO - Exporting the following env vars:
AIRFLOW_CTX_DAG_EMAIL=alexander.fournier@gmail.com
AIRFLOW_CTX_DAG_OWNER=Alexander Fournier
AIRFLOW_CTX_DAG_ID=Neo4jOlympicsDemo
AIRFLOW_CTX_TASK_ID=create-db
AIRFLOW_CTX_EXECUTION_DATE=2021-10-18T20:38:18.935137+00:00
AIRFLOW_CTX_DAG_RUN_ID=manual__2021-10-18T20:38:18.935137+00:00
[2021-10-18 20:44:18,752] {simple.py:361} WARNING - Transaction failed and will be retried in 0.9959179212703559s (Couldn't connect to 127.0.0.1:7687 (resolved to ('127.0.0.1:7687',)):
Failed to establish connection to ResolvedIPv4Address(('127.0.0.1', 7687)) (reason [Errno 111] Connection refused))
[2021-10-18 20:44:19,749] {simple.py:361} WARNING - Transaction failed and will be retried in 2.052442287619309s (Couldn't connect to 127.0.0.1:7687 (resolved to ('127.0.0.1:7687',)):
Failed to establish connection to ResolvedIPv4Address(('127.0.0.1', 7687)) (reason [Errno 111] Connection refused))
[2021-10-18 20:44:21,804] {simple.py:361} WARNING - Transaction failed and will be retried in 3.944826901284462s (Couldn't connect to 127.0.0.1:7687 (resolved to ('127.0.0.1:7687',)):
Failed to establish connection to ResolvedIPv4Address(('127.0.0.1', 7687)) (reason [Errno 111] Connection refused))
[2021-10-18 20:44:25,755] {simple.py:361} WARNING - Transaction failed and will be retried in 8.205300111871818s (Couldn't connect to 127.0.0.1:7687 (resolved to ('127.0.0.1:7687',)):
Failed to establish connection to ResolvedIPv4Address(('127.0.0.1', 7687)) (reason [Errno 111] Connection refused))
[2021-10-18 20:44:33,949] {simple.py:361} WARNING - Transaction failed and will be retried in 14.569736607669716s (Couldn't connect to 127.0.0.1:7687 (resolved to ('127.0.0.1:7687',)):
Failed to establish connection to ResolvedIPv4Address(('127.0.0.1', 7687)) (reason [Errno 111] Connection refused))
